<?xml version="1.0" ?>
<robot name="falcon" xmlns:xacro="http://www.ros.org/wiki/xacro">

<xacro:include filename="$(find falcon_description)/Gazebo/falcon_materials.gazebo" />
<xacro:include filename="$(find falcon_description)/Gazebo/falcon_physics.gazebo" />
<xacro:include filename="$(find falcon_description)/Gazebo/falcon_plugins.gazebo" />
<link name="base_link">
  <inertial>
    <origin rpy="0 0 0" xyz="-9.67857151412328e-16 -2.6593643350620014e-17 0.05230314967854302"/>
    <mass value="0.402909257822891"/>
    <inertia ixx="0.002267" ixy="-0.0" ixz="0.0" iyy="0.002267" iyz="-0.0" izz="0.004533"/>
  </inertial>
  <visual>
    <origin rpy="0 0 0" xyz="0 0 0"/>
    <geometry>
      <mesh filename="package://falcon_description/meshes/base_link.stl" scale="0.001 0.001 0.001"/>
    </geometry>
    <material name="silver_default"/>
  </visual>
  <collision>
    <origin rpy="0 0 0" xyz="0 0 0"/>
    <geometry>
      <mesh filename="package://falcon_description/meshes/base_link.stl" scale="0.001 0.001 0.001"/>
    </geometry>
  </collision>
</link>

<link name="sd2_1">
  <inertial>
    <origin rpy="0 0 0" xyz="0.10499999999999905 -0.07700000000000001 0.04000014967854306"/>
    <mass value="0.05438639535766264"/>
    <inertia ixx="2.9e-05" ixy="-0.0" ixz="-0.0" iyy="2.9e-05" iyz="-0.0" izz="1e-06"/>
  </inertial>
  <visual>
    <origin rpy="0 0 0" xyz="0.0 0.0 -0.054303"/>
    <geometry>
      <mesh filename="package://falcon_description/meshes/sd2_1.stl" scale="0.001 0.001 0.001"/>
    </geometry>
    <material name="silver_default"/>
  </visual>
  <collision>
    <origin rpy="0 0 0" xyz="0.0 0.0 -0.054303"/>
    <geometry>
      <mesh filename="package://falcon_description/meshes/sd2_1.stl" scale="0.001 0.001 0.001"/>
    </geometry>
  </collision>
</link>

<link name="sd4_1">
  <inertial>
    <origin rpy="0 0 0" xyz="0.10499999999999896 0.07499999999999998 0.04000014967854299"/>
    <mass value="0.05438639535766264"/>
    <inertia ixx="2.9e-05" ixy="-0.0" ixz="-0.0" iyy="2.9e-05" iyz="-0.0" izz="1e-06"/>
  </inertial>
  <visual>
    <origin rpy="0 0 0" xyz="0.0 0.0 -0.054303"/>
    <geometry>
      <mesh filename="package://falcon_description/meshes/sd4_1.stl" scale="0.001 0.001 0.001"/>
    </geometry>
    <material name="silver_default"/>
  </visual>
  <collision>
    <origin rpy="0 0 0" xyz="0.0 0.0 -0.054303"/>
    <geometry>
      <mesh filename="package://falcon_description/meshes/sd4_1.stl" scale="0.001 0.001 0.001"/>
    </geometry>
  </collision>
</link>

<link name="sd3_1">
  <inertial>
    <origin rpy="0 0 0" xyz="-0.105000000000001 0.07499999999999998 0.040000149678543005"/>
    <mass value="0.05438639535766264"/>
    <inertia ixx="2.9e-05" ixy="-0.0" ixz="0.0" iyy="2.9e-05" iyz="-0.0" izz="1e-06"/>
  </inertial>
  <visual>
    <origin rpy="0 0 0" xyz="0.0 0.0 -0.054303"/>
    <geometry>
      <mesh filename="package://falcon_description/meshes/sd3_1.stl" scale="0.001 0.001 0.001"/>
    </geometry>
    <material name="silver_default"/>
  </visual>
  <collision>
    <origin rpy="0 0 0" xyz="0.0 0.0 -0.054303"/>
    <geometry>
      <mesh filename="package://falcon_description/meshes/sd3_1.stl" scale="0.001 0.001 0.001"/>
    </geometry>
  </collision>
</link>

<link name="sd1_1">
  <inertial>
    <origin rpy="0 0 0" xyz="-0.10500000000000088 -0.07500000000000002 0.040000149678543116"/>
    <mass value="0.05438639535766264"/>
    <inertia ixx="2.9e-05" ixy="-0.0" ixz="-0.0" iyy="2.9e-05" iyz="-0.0" izz="1e-06"/>
  </inertial>
  <visual>
    <origin rpy="0 0 0" xyz="0.0 0.0 -0.054303"/>
    <geometry>
      <mesh filename="package://falcon_description/meshes/sd1_1.stl" scale="0.001 0.001 0.001"/>
    </geometry>
    <material name="silver_default"/>
  </visual>
  <collision>
    <origin rpy="0 0 0" xyz="0.0 0.0 -0.054303"/>
    <geometry>
      <mesh filename="package://falcon_description/meshes/sd1_1.stl" scale="0.001 0.001 0.001"/>
    </geometry>
  </collision>
</link>

<link name="upper_plate_1">
  <inertial>
    <origin rpy="0 0 0" xyz="0.09832597061337654 -0.07718105902070528 0.0020001496785430617"/>
    <mass value="0.4029092578228913"/>
    <inertia ixx="0.002267" ixy="0.0" ixz="-0.0" iyy="0.002267" iyz="-0.0" izz="0.004533"/>
  </inertial>
  <visual>
    <origin rpy="0 0 0" xyz="0.10017 -0.076294 -0.134303"/>
    <geometry>
      <mesh filename="package://falcon_description/meshes/upper_plate_1.stl" scale="0.001 0.001 0.001"/>
    </geometry>
    <material name="silver_default"/>
  </visual>
  <collision>
    <origin rpy="0 0 0" xyz="0.10017 -0.076294 -0.134303"/>
    <geometry>
      <mesh filename="package://falcon_description/meshes/upper_plate_1.stl" scale="0.001 0.001 0.001"/>
    </geometry>
  </collision>
</link>

<link name="Arduino_uno.6df525b0-a0fc-4683-8e1a-4d70c617ad71_v1_1">
  <inertial>
    <origin rpy="0 0 0" xyz="-0.03155432138817296 0.00713228233557432 0.005306319016284623"/>
    <mass value="0.057955713973018276"/>
    <inertia ixx="2.7e-05" ixy="-3e-06" ixz="-0.0" iyy="1.7e-05" iyz="-1e-06" izz="4.3e-05"/>
  </inertial>
  <visual>
    <origin rpy="0 0 0" xyz="0.0 0.0 -0.054303"/>
    <geometry>
      <mesh filename="package://falcon_description/meshes/Arduino_uno.6df525b0-a0fc-4683-8e1a-4d70c617ad71_v1_1.stl" scale="0.001 0.001 0.001"/>
    </geometry>
    <material name="silver_default"/>
  </visual>
  <collision>
    <origin rpy="0 0 0" xyz="0.0 0.0 -0.054303"/>
    <geometry>
      <mesh filename="package://falcon_description/meshes/Arduino_uno.6df525b0-a0fc-4683-8e1a-4d70c617ad71_v1_1.stl" scale="0.001 0.001 0.001"/>
    </geometry>
  </collision>
</link>

<link name="wheels_v2_1">
  <inertial>
    <origin rpy="0 0 0" xyz="-8.15466474443638e-07 -0.017807485643427656 3.8670790783457143e-07"/>
    <mass value="0.18220368816055363"/>
    <inertia ixx="6.7e-05" ixy="0.0" ixz="-0.0" iyy="0.000121" iyz="-0.0" izz="6.7e-05"/>
  </inertial>
  <visual>
    <origin rpy="0 0 0" xyz="0.0835 0.1525 -0.038122"/>
    <geometry>
      <mesh filename="package://falcon_description/meshes/wheels_v2_1.stl" scale="0.001 0.001 0.001"/>
    </geometry>
    <material name="silver_default"/>
  </visual>
  <collision>
    <origin rpy="0 0 0" xyz="0.0835 0.1525 -0.038122"/>
    <geometry>
      <mesh filename="package://falcon_description/meshes/wheels_v2_1.stl" scale="0.001 0.001 0.001"/>
    </geometry>
  </collision>
</link>

<link name="wheels_v2_2">
  <inertial>
    <origin rpy="0 0 0" xyz="-8.154664748460938e-07 0.017807485643427545 3.8670789302003294e-07"/>
    <mass value="0.18220368816055363"/>
    <inertia ixx="6.7e-05" ixy="-0.0" ixz="0.0" iyy="0.000121" iyz="-0.0" izz="6.7e-05"/>
  </inertial>
  <visual>
    <origin rpy="0 0 0" xyz="0.0837 -0.1525 -0.038122"/>
    <geometry>
      <mesh filename="package://falcon_description/meshes/wheels_v2_2.stl" scale="0.001 0.001 0.001"/>
    </geometry>
    <material name="silver_default"/>
  </visual>
  <collision>
    <origin rpy="0 0 0" xyz="0.0837 -0.1525 -0.038122"/>
    <geometry>
      <mesh filename="package://falcon_description/meshes/wheels_v2_2.stl" scale="0.001 0.001 0.001"/>
    </geometry>
  </collision>
</link>

<link name="motor_left_v1_1">
  <inertial>
    <origin rpy="0 0 0" xyz="-0.08350000000000087 -0.10628292124886941 -0.012180613292093606"/>
    <mass value="0.252461303560872"/>
    <inertia ixx="0.000164" ixy="-0.0" ixz="0.0" iyy="1.7e-05" iyz="0.0" izz="0.000166"/>
  </inertial>
  <visual>
    <origin rpy="0 0 0" xyz="0.0 0.0 -0.050303"/>
    <geometry>
      <mesh filename="package://falcon_description/meshes/motor_left_v1_1.stl" scale="0.001 0.001 0.001"/>
    </geometry>
    <material name="silver_default"/>
  </visual>
  <collision>
    <origin rpy="0 0 0" xyz="0.0 0.0 -0.050303"/>
    <geometry>
      <mesh filename="package://falcon_description/meshes/motor_left_v1_1.stl" scale="0.001 0.001 0.001"/>
    </geometry>
  </collision>
</link>

<link name="motor_right_v1_v1_1">
  <inertial>
    <origin rpy="0 0 0" xyz="-0.0837000000000012 0.10628292124886932 -0.016180613292093818"/>
    <mass value="0.252461303560872"/>
    <inertia ixx="0.000164" ixy="0.0" ixz="0.0" iyy="1.7e-05" iyz="-0.0" izz="0.000166"/>
  </inertial>
  <visual>
    <origin rpy="0 0 0" xyz="0.0 0.0 -0.054303"/>
    <geometry>
      <mesh filename="package://falcon_description/meshes/motor_right_v1_v1_1.stl" scale="0.001 0.001 0.001"/>
    </geometry>
    <material name="silver_default"/>
  </visual>
  <collision>
    <origin rpy="0 0 0" xyz="0.0 0.0 -0.054303"/>
    <geometry>
      <mesh filename="package://falcon_description/meshes/motor_right_v1_v1_1.stl" scale="0.001 0.001 0.001"/>
    </geometry>
  </collision>
</link>

<link name="Raspberry-Pi-4-Model-B-03_v1_1">
  <inertial>
    <origin rpy="0 0 0" xyz="0.04903732841291807 0.015143940045604574 0.00544862297481357"/>
    <mass value="0.11046204859047104"/>
    <inertia ixx="7.4e-05" ixy="-2e-06" ixz="-0.0" iyy="3.3e-05" iyz="-7e-06" izz="0.000102"/>
  </inertial>
  <visual>
    <origin rpy="0 0 0" xyz="0.0 0.0 -0.054303"/>
    <geometry>
      <mesh filename="package://falcon_description/meshes/Raspberry-Pi-4-Model-B-03_v1_1.stl" scale="0.001 0.001 0.001"/>
    </geometry>
    <material name="silver_default"/>
  </visual>
  <collision>
    <origin rpy="0 0 0" xyz="0.0 0.0 -0.054303"/>
    <geometry>
      <mesh filename="package://falcon_description/meshes/Raspberry-Pi-4-Model-B-03_v1_1.stl" scale="0.001 0.001 0.001"/>
    </geometry>
  </collision>
</link>

<link name="l298n__v12_1">
  <inertial>
    <origin rpy="0 0 0" xyz="-0.09124354847663095 0.00164655591312931 0.008981004617545911"/>
    <mass value="0.07894628453414008"/>
    <inertia ixx="1.7e-05" ixy="-1e-06" ixz="0.0" iyy="1.3e-05" iyz="-3e-06" izz="2.2e-05"/>
  </inertial>
  <visual>
    <origin rpy="0 0 0" xyz="0.0 0.0 -0.054303"/>
    <geometry>
      <mesh filename="package://falcon_description/meshes/l298n__v12_1.stl" scale="0.001 0.001 0.001"/>
    </geometry>
    <material name="silver_default"/>
  </visual>
  <collision>
    <origin rpy="0 0 0" xyz="0.0 0.0 -0.054303"/>
    <geometry>
      <mesh filename="package://falcon_description/meshes/l298n__v12_1.stl" scale="0.001 0.001 0.001"/>
    </geometry>
  </collision>
</link>

<link name="power_bank.f96af03a-0fb2-4191-ac78-a015be66eb68_v2_1">
  <inertial>
    <origin rpy="0 0 0" xyz="-0.012572936969995589 0.000265889694991782 -0.012493581581072576"/>
    <mass value="0.5416823843699559"/>
    <inertia ixx="0.000242" ixy="-1e-06" ixz="0.0" iyy="0.000122" iyz="0.0" izz="0.000313"/>
  </inertial>
  <visual>
    <origin rpy="0 0 0" xyz="0.0 0.0 -0.050303"/>
    <geometry>
      <mesh filename="package://falcon_description/meshes/power_bank.f96af03a-0fb2-4191-ac78-a015be66eb68_v2_1.stl" scale="0.001 0.001 0.001"/>
    </geometry>
    <material name="silver_default"/>
  </visual>
  <collision>
    <origin rpy="0 0 0" xyz="0.0 0.0 -0.050303"/>
    <geometry>
      <mesh filename="package://falcon_description/meshes/power_bank.f96af03a-0fb2-4191-ac78-a015be66eb68_v2_1.stl" scale="0.001 0.001 0.001"/>
    </geometry>
  </collision>
</link>

<link name="MODULO_XL4016_v1_1">
  <inertial>
    <origin rpy="0 0 0" xyz="0.003496342778758418 0.10000457758500424 0.009725545612401819"/>
    <mass value="0.162841989737334"/>
    <inertia ixx="2.9e-05" ixy="0.0" ixz="-2e-06" iyy="4.9e-05" iyz="0.0" izz="6.5e-05"/>
  </inertial>
  <visual>
    <origin rpy="0 0 0" xyz="0.0 0.0 -0.054303"/>
    <geometry>
      <mesh filename="package://falcon_description/meshes/MODULO_XL4016_v1_1.stl" scale="0.001 0.001 0.001"/>
    </geometry>
    <material name="silver_default"/>
  </visual>
  <collision>
    <origin rpy="0 0 0" xyz="0.0 0.0 -0.054303"/>
    <geometry>
      <mesh filename="package://falcon_description/meshes/MODULO_XL4016_v1_1.stl" scale="0.001 0.001 0.001"/>
    </geometry>
  </collision>
</link>

<link name="GY-91_MPU9250+BMP280_-_Pins_Down__1__v1_1">
  <inertial>
    <origin rpy="0 0 0" xyz="-0.0008173970150823031 -0.10039875418246057 0.0010166475259210106"/>
    <mass value="0.004104865550111833"/>
    <inertia ixx="0.0" ixy="-0.0" ixz="0.0" iyy="0.0" iyz="0.0" izz="0.0"/>
  </inertial>
  <visual>
    <origin rpy="0 0 0" xyz="0.0 0.0 -0.054303"/>
    <geometry>
      <mesh filename="package://falcon_description/meshes/GY-91_MPU9250+BMP280_-_Pins_Down__1__v1_1.stl" scale="0.001 0.001 0.001"/>
    </geometry>
    <material name="silver_default"/>
  </visual>
  <collision>
    <origin rpy="0 0 0" xyz="0.0 0.0 -0.054303"/>
    <geometry>
      <mesh filename="package://falcon_description/meshes/GY-91_MPU9250+BMP280_-_Pins_Down__1__v1_1.stl" scale="0.001 0.001 0.001"/>
    </geometry>
  </collision>
</link>

<link name="caster_2">
  <inertial>
    <origin rpy="0 0 0" xyz="0.11999999999999904 1.2005651613934594e-17 -0.022638739210345857"/>
    <mass value="0.24969771109813355"/>
    <inertia ixx="5.7e-05" ixy="-0.0" ixz="-0.0" iyy="5.7e-05" iyz="-0.0" izz="2.7e-05"/>
  </inertial>
  <visual>
    <origin rpy="0 0 0" xyz="0.0 0.0 -0.050303"/>
    <geometry>
      <mesh filename="package://falcon_description/meshes/caster_2.stl" scale="0.001 0.001 0.001"/>
    </geometry>
    <material name="silver_default"/>
  </visual>
  <collision>
    <origin rpy="0 0 0" xyz="0.0 0.0 -0.050303"/>
    <geometry>
      <mesh filename="package://falcon_description/meshes/caster_2.stl" scale="0.001 0.001 0.001"/>
    </geometry>
  </collision>
</link>

<link name="lidar_v1_1">
  <inertial>
    <origin rpy="0 0 0" xyz="0.049578486108768874 0.005044839637171208 0.03526833392576614"/>
    <mass value="1.3392964352221826"/>
    <inertia ixx="0.000619" ixy="-1e-06" ixz="-0.000159" iyy="0.000967" iyz="3e-06" izz="0.001105"/>
  </inertial>
  <visual>
    <origin rpy="0 0 0" xyz="0.001844 0.000887 -0.138303"/>
    <geometry>
      <mesh filename="package://falcon_description/meshes/lidar_v1_1.stl" scale="0.001 0.001 0.001"/>
    </geometry>
    <material name="silver_default"/>
  </visual>
  <collision>
    <origin rpy="0 0 0" xyz="0.001844 0.000887 -0.138303"/>
    <geometry>
      <mesh filename="package://falcon_description/meshes/lidar_v1_1.stl" scale="0.001 0.001 0.001"/>
    </geometry>
  </collision>
</link>

<link name="camera_1">
  <inertial>
    <origin rpy="0 0 0" xyz="0.1312482542175321 -0.001066853735353874 -0.026945495496267832"/>
    <mass value="0.0465939448735046"/>
    <inertia ixx="1.5e-05" ixy="-0.0" ixz="0.0" iyy="8e-06" iyz="0.0" izz="8e-06"/>
  </inertial>
  <visual>
    <origin rpy="0 0 0" xyz="0.001844 0.000887 -0.138303"/>
    <geometry>
      <mesh filename="package://falcon_description/meshes/camera_1.stl" scale="0.001 0.001 0.001"/>
    </geometry>
    <material name="silver_default"/>
  </visual>
  <collision>
    <origin rpy="0 0 0" xyz="0.001844 0.000887 -0.138303"/>
    <geometry>
      <mesh filename="package://falcon_description/meshes/camera_1.stl" scale="0.001 0.001 0.001"/>
    </geometry>
  </collision>
</link>






<joint name="Rigid1" type="fixed">
  <origin rpy="0 0 0" xyz="0.0 0.0 0.054303"/>
  <parent link="base_link"/>
  <child link="sd2_1"/>
</joint>

<joint name="Rigid2" type="fixed">
  <origin rpy="0 0 0" xyz="0.0 0.0 0.054303"/>
  <parent link="base_link"/>
  <child link="sd4_1"/>
</joint>

<joint name="Rigid3" type="fixed">
  <origin rpy="0 0 0" xyz="0.0 0.0 0.054303"/>
  <parent link="base_link"/>
  <child link="sd3_1"/>
</joint>

<joint name="Rigid4" type="fixed">
  <origin rpy="0 0 0" xyz="0.0 0.0 0.054303"/>
  <parent link="base_link"/>
  <child link="sd1_1"/>
</joint>

<joint name="Rigid5" type="fixed">
  <origin rpy="0 0 0" xyz="-0.10017 0.076294 0.08"/>
  <parent link="sd3_1"/>
  <child link="upper_plate_1"/>
</joint>

<joint name="Rigid6" type="fixed">
  <origin rpy="0 0 0" xyz="0.0 0.0 0.054303"/>
  <parent link="base_link"/>
  <child link="Arduino_uno.6df525b0-a0fc-4683-8e1a-4d70c617ad71_v1_1"/>
</joint>

<joint name="Rev9" type="continuous">
  <origin rpy="0 0 0" xyz="-0.0835 -0.1525 -0.012181"/>
  <parent link="motor_left_v1_1"/>
  <child link="wheels_v2_1"/>
  <axis xyz="0.0 1.0 0.0"/>
</joint>

<joint name="Rev10" type="continuous">
  <origin rpy="0 0 0" xyz="-0.0837 0.1525 -0.016181"/>
  <parent link="motor_right_v1_v1_1"/>
  <child link="wheels_v2_2"/>
  <axis xyz="0.0 1.0 0.0"/>
</joint>

<joint name="Rigid12" type="fixed">
  <origin rpy="0 0 0" xyz="0.0 0.0 0.050303"/>
  <parent link="base_link"/>
  <child link="motor_left_v1_1"/>
</joint>

<joint name="Rigid13" type="fixed">
  <origin rpy="0 0 0" xyz="0.0 0.0 0.054303"/>
  <parent link="base_link"/>
  <child link="motor_right_v1_v1_1"/>
</joint>

<joint name="Rigid14" type="fixed">
  <origin rpy="0 0 0" xyz="0.0 0.0 0.054303"/>
  <parent link="base_link"/>
  <child link="Raspberry-Pi-4-Model-B-03_v1_1"/>
</joint>

<joint name="Rigid15" type="fixed">
  <origin rpy="0 0 0" xyz="0.0 0.0 0.054303"/>
  <parent link="base_link"/>
  <child link="l298n__v12_1"/>
</joint>

<joint name="Rigid16" type="fixed">
  <origin rpy="0 0 0" xyz="0.0 0.0 0.050303"/>
  <parent link="base_link"/>
  <child link="power_bank.f96af03a-0fb2-4191-ac78-a015be66eb68_v2_1"/>
</joint>

<joint name="Rigid17" type="fixed">
  <origin rpy="0 0 0" xyz="0.0 0.0 0.054303"/>
  <parent link="base_link"/>
  <child link="MODULO_XL4016_v1_1"/>
</joint>

<joint name="Rigid19" type="fixed">
  <origin rpy="0 0 0" xyz="0.0 0.0 0.054303"/>
  <parent link="base_link"/>
  <child link="GY-91_MPU9250+BMP280_-_Pins_Down__1__v1_1"/>
</joint>

<joint name="Rigid21" type="fixed">
  <origin rpy="0 0 0" xyz="0.0 0.0 0.050303"/>
  <parent link="base_link"/>
  <child link="caster_2"/>
</joint>

<joint name="Rigid24" type="fixed">
  <origin rpy="0 0 0" xyz="0.098326 -0.077181 0.004"/>
  <parent link="upper_plate_1"/>
  <child link="lidar_v1_1"/>
</joint>

<joint name="Rigid25" type="fixed">
  <origin rpy="0 0 0" xyz="0.098326 -0.077181 0.004"/>
  <parent link="upper_plate_1"/>
  <child link="camera_1"/>
</joint>

</robot>
