<?xml version="1.0" ?>
<robot name="falcon" xmlns:xacro="http://www.ros.org/wiki/xacro">

<xacro:include filename="$(find falcon_description)/urdf/materials.xacro" />
<xacro:include filename="$(find falcon_description)/urdf/falcon.trans" />
<xacro:include filename="$(find falcon_description)/urdf/falcon.gazebo" />
<link name="base_link">
  <inertial>
    <origin rpy="0 0 0" xyz="-9.589753672153266e-16 -2.6593643350619493e-17 0.05230314967854301"/>
    <mass value="0.402909257822891"/>
    <inertia ixx="0.002267" ixy="-0.0" ixz="0.0" iyy="0.002267" iyz="-0.0" izz="0.004533"/>
  </inertial>
  <visual>
    <origin rpy="0 0 0" xyz="0 0 0"/>
    <geometry>
      <mesh filename="package://falcon_description/meshes/base_link.stl" scale="0.001 0.001 0.001"/>
    </geometry>
    <material name="silver_default"/>
  </visual>
  <collision>
    <origin rpy="0 0 0" xyz="0 0 0"/>
    <geometry>
      <mesh filename="package://falcon_description/meshes/base_link.stl" scale="0.001 0.001 0.001"/>
    </geometry>
  </collision>
</link>

<link name="sd2_1">
  <inertial>
    <origin rpy="0 0 0" xyz="0.10499999999999923 -0.07700000000000011 0.04000014967854305"/>
    <mass value="0.05438639535766264"/>
    <inertia ixx="2.9e-05" ixy="-0.0" ixz="0.0" iyy="2.9e-05" iyz="-0.0" izz="1e-06"/>
  </inertial>
  <visual>
    <origin rpy="0 0 0" xyz="0.0 0.0 -0.054303"/>
    <geometry>
      <mesh filename="package://falcon_description/meshes/sd2_1.stl" scale="0.001 0.001 0.001"/>
    </geometry>
    <material name="silver_default"/>
  </visual>
  <collision>
    <origin rpy="0 0 0" xyz="0.0 0.0 -0.054303"/>
    <geometry>
      <mesh filename="package://falcon_description/meshes/sd2_1.stl" scale="0.001 0.001 0.001"/>
    </geometry>
  </collision>
</link>

<link name="sd4_1">
  <inertial>
    <origin rpy="0 0 0" xyz="0.1049999999999991 0.07500000000000007 0.040000149678542964"/>
    <mass value="0.05438639535766264"/>
    <inertia ixx="2.9e-05" ixy="-0.0" ixz="0.0" iyy="2.9e-05" iyz="-0.0" izz="1e-06"/>
  </inertial>
  <visual>
    <origin rpy="0 0 0" xyz="0.0 0.0 -0.054303"/>
    <geometry>
      <mesh filename="package://falcon_description/meshes/sd4_1.stl" scale="0.001 0.001 0.001"/>
    </geometry>
    <material name="silver_default"/>
  </visual>
  <collision>
    <origin rpy="0 0 0" xyz="0.0 0.0 -0.054303"/>
    <geometry>
      <mesh filename="package://falcon_description/meshes/sd4_1.stl" scale="0.001 0.001 0.001"/>
    </geometry>
  </collision>
</link>

<link name="sd3_1">
  <inertial>
    <origin rpy="0 0 0" xyz="-0.10500000000000115 0.07500000000000007 0.04000014967854299"/>
    <mass value="0.05438639535766264"/>
    <inertia ixx="2.9e-05" ixy="-0.0" ixz="0.0" iyy="2.9e-05" iyz="-0.0" izz="1e-06"/>
  </inertial>
  <visual>
    <origin rpy="0 0 0" xyz="0.0 0.0 -0.054303"/>
    <geometry>
      <mesh filename="package://falcon_description/meshes/sd3_1.stl" scale="0.001 0.001 0.001"/>
    </geometry>
    <material name="silver_default"/>
  </visual>
  <collision>
    <origin rpy="0 0 0" xyz="0.0 0.0 -0.054303"/>
    <geometry>
      <mesh filename="package://falcon_description/meshes/sd3_1.stl" scale="0.001 0.001 0.001"/>
    </geometry>
  </collision>
</link>

<link name="sd1_1">
  <inertial>
    <origin rpy="0 0 0" xyz="-0.10500000000000101 -0.07500000000000011 0.04000014967854306"/>
    <mass value="0.05438639535766264"/>
    <inertia ixx="2.9e-05" ixy="-0.0" ixz="0.0" iyy="2.9e-05" iyz="-0.0" izz="1e-06"/>
  </inertial>
  <visual>
    <origin rpy="0 0 0" xyz="0.0 0.0 -0.054303"/>
    <geometry>
      <mesh filename="package://falcon_description/meshes/sd1_1.stl" scale="0.001 0.001 0.001"/>
    </geometry>
    <material name="silver_default"/>
  </visual>
  <collision>
    <origin rpy="0 0 0" xyz="0.0 0.0 -0.054303"/>
    <geometry>
      <mesh filename="package://falcon_description/meshes/sd1_1.stl" scale="0.001 0.001 0.001"/>
    </geometry>
  </collision>
</link>

<link name="upper_plate_1">
  <inertial>
    <origin rpy="0 0 0" xyz="0.09832597061337656 -0.07718105902070528 0.002000149678543006"/>
    <mass value="0.4029092578228913"/>
    <inertia ixx="0.002267" ixy="0.0" ixz="-0.0" iyy="0.002267" iyz="-0.0" izz="0.004533"/>
  </inertial>
  <visual>
    <origin rpy="0 0 0" xyz="0.10017 -0.076294 -0.134303"/>
    <geometry>
      <mesh filename="package://falcon_description/meshes/upper_plate_1.stl" scale="0.001 0.001 0.001"/>
    </geometry>
    <material name="silver_default"/>
  </visual>
  <collision>
    <origin rpy="0 0 0" xyz="0.10017 -0.076294 -0.134303"/>
    <geometry>
      <mesh filename="package://falcon_description/meshes/upper_plate_1.stl" scale="0.001 0.001 0.001"/>
    </geometry>
  </collision>
</link>

<link name="Arduino_uno.6df525b0-a0fc-4683-8e1a-4d70c617ad71_v1_1">
  <inertial>
    <origin rpy="0 0 0" xyz="0.00713228233557339 0.031554321388171935 0.00630631901628461"/>
    <mass value="0.057955713973018276"/>
    <inertia ixx="1.7e-05" ixy="3e-06" ixz="-1e-06" iyy="2.7e-05" iyz="0.0" izz="4.3e-05"/>
  </inertial>
  <visual>
    <origin rpy="0 0 0" xyz="0.0 0.0 -0.054303"/>
    <geometry>
      <mesh filename="package://falcon_description/meshes/Arduino_uno.6df525b0-a0fc-4683-8e1a-4d70c617ad71_v1_1.stl" scale="0.001 0.001 0.001"/>
    </geometry>
    <material name="silver_default"/>
  </visual>
  <collision>
    <origin rpy="0 0 0" xyz="0.0 0.0 -0.054303"/>
    <geometry>
      <mesh filename="package://falcon_description/meshes/Arduino_uno.6df525b0-a0fc-4683-8e1a-4d70c617ad71_v1_1.stl" scale="0.001 0.001 0.001"/>
    </geometry>
  </collision>
</link>

<link name="wheels_v2_1">
  <inertial>
    <origin rpy="0 0 0" xyz="-8.15466474443638e-07 -0.01780748564342788 3.867079078553881e-07"/>
    <mass value="0.18220368816055363"/>
    <inertia ixx="6.7e-05" ixy="0.0" ixz="-0.0" iyy="0.000121" iyz="-0.0" izz="6.7e-05"/>
  </inertial>
  <visual>
    <origin rpy="0 0 0" xyz="0.0835 0.1525 -0.038122"/>
    <geometry>
      <mesh filename="package://falcon_description/meshes/wheels_v2_1.stl" scale="0.001 0.001 0.001"/>
    </geometry>
    <material name="silver_default"/>
  </visual>
  <collision>
    <origin rpy="0 0 0" xyz="0.0835 0.1525 -0.038122"/>
    <geometry>
      <mesh filename="package://falcon_description/meshes/wheels_v2_1.stl" scale="0.001 0.001 0.001"/>
    </geometry>
  </collision>
</link>

<link name="wheels_v2_2">
  <inertial>
    <origin rpy="0 0 0" xyz="-8.154664748460938e-07 0.017807485643427767 3.8670789300615516e-07"/>
    <mass value="0.18220368816055363"/>
    <inertia ixx="6.7e-05" ixy="-0.0" ixz="0.0" iyy="0.000121" iyz="-0.0" izz="6.7e-05"/>
  </inertial>
  <visual>
    <origin rpy="0 0 0" xyz="0.0837 -0.1525 -0.038122"/>
    <geometry>
      <mesh filename="package://falcon_description/meshes/wheels_v2_2.stl" scale="0.001 0.001 0.001"/>
    </geometry>
    <material name="silver_default"/>
  </visual>
  <collision>
    <origin rpy="0 0 0" xyz="0.0837 -0.1525 -0.038122"/>
    <geometry>
      <mesh filename="package://falcon_description/meshes/wheels_v2_2.stl" scale="0.001 0.001 0.001"/>
    </geometry>
  </collision>
</link>

<link name="motor_left_v1_1">
  <inertial>
    <origin rpy="0 0 0" xyz="-0.08350000000000099 -0.10628292124886961 -0.012180613292093627"/>
    <mass value="0.252461303560872"/>
    <inertia ixx="0.000164" ixy="-0.0" ixz="0.0" iyy="1.7e-05" iyz="0.0" izz="0.000166"/>
  </inertial>
  <visual>
    <origin rpy="0 0 0" xyz="0.0 0.0 -0.050303"/>
    <geometry>
      <mesh filename="package://falcon_description/meshes/motor_left_v1_1.stl" scale="0.001 0.001 0.001"/>
    </geometry>
    <material name="silver_default"/>
  </visual>
  <collision>
    <origin rpy="0 0 0" xyz="0.0 0.0 -0.050303"/>
    <geometry>
      <mesh filename="package://falcon_description/meshes/motor_left_v1_1.stl" scale="0.001 0.001 0.001"/>
    </geometry>
  </collision>
</link>

<link name="motor_right_v1_v1_1">
  <inertial>
    <origin rpy="0 0 0" xyz="-0.08370000000000127 0.10628292124886936 -0.01618061329209381"/>
    <mass value="0.252461303560872"/>
    <inertia ixx="0.000164" ixy="0.0" ixz="0.0" iyy="1.7e-05" iyz="-0.0" izz="0.000166"/>
  </inertial>
  <visual>
    <origin rpy="0 0 0" xyz="0.0 0.0 -0.054303"/>
    <geometry>
      <mesh filename="package://falcon_description/meshes/motor_right_v1_v1_1.stl" scale="0.001 0.001 0.001"/>
    </geometry>
    <material name="silver_default"/>
  </visual>
  <collision>
    <origin rpy="0 0 0" xyz="0.0 0.0 -0.054303"/>
    <geometry>
      <mesh filename="package://falcon_description/meshes/motor_right_v1_v1_1.stl" scale="0.001 0.001 0.001"/>
    </geometry>
  </collision>
</link>

<link name="Raspberry-Pi-4-Model-B-03_v1_1">
  <inertial>
    <origin rpy="0 0 0" xyz="0.049037328412918316 0.015143940045604433 0.005448622974813473"/>
    <mass value="0.11046204859047104"/>
    <inertia ixx="7.4e-05" ixy="-2e-06" ixz="-0.0" iyy="3.3e-05" iyz="-7e-06" izz="0.000102"/>
  </inertial>
  <visual>
    <origin rpy="0 0 0" xyz="0.0 0.0 -0.054303"/>
    <geometry>
      <mesh filename="package://falcon_description/meshes/Raspberry-Pi-4-Model-B-03_v1_1.stl" scale="0.001 0.001 0.001"/>
    </geometry>
    <material name="silver_default"/>
  </visual>
  <collision>
    <origin rpy="0 0 0" xyz="0.0 0.0 -0.054303"/>
    <geometry>
      <mesh filename="package://falcon_description/meshes/Raspberry-Pi-4-Model-B-03_v1_1.stl" scale="0.001 0.001 0.001"/>
    </geometry>
  </collision>
</link>

<link name="l298n__v12_1">
  <inertial>
    <origin rpy="0 0 0" xyz="-0.09124354847663085 0.001646555913129146 0.008981004617545814"/>
    <mass value="0.07894628453414008"/>
    <inertia ixx="1.7e-05" ixy="-1e-06" ixz="0.0" iyy="1.3e-05" iyz="-3e-06" izz="2.2e-05"/>
  </inertial>
  <visual>
    <origin rpy="0 0 0" xyz="0.0 0.0 -0.054303"/>
    <geometry>
      <mesh filename="package://falcon_description/meshes/l298n__v12_1.stl" scale="0.001 0.001 0.001"/>
    </geometry>
    <material name="silver_default"/>
  </visual>
  <collision>
    <origin rpy="0 0 0" xyz="0.0 0.0 -0.054303"/>
    <geometry>
      <mesh filename="package://falcon_description/meshes/l298n__v12_1.stl" scale="0.001 0.001 0.001"/>
    </geometry>
  </collision>
</link>

<link name="power_bank.f96af03a-0fb2-4191-ac78-a015be66eb68_v2_1">
  <inertial>
    <origin rpy="0 0 0" xyz="-0.012572936969995426 0.00026588969499163987 -0.012493581581072659"/>
    <mass value="0.5416823843699559"/>
    <inertia ixx="0.000242" ixy="-1e-06" ixz="0.0" iyy="0.000122" iyz="0.0" izz="0.000313"/>
  </inertial>
  <visual>
    <origin rpy="0 0 0" xyz="0.0 0.0 -0.050303"/>
    <geometry>
      <mesh filename="package://falcon_description/meshes/power_bank.f96af03a-0fb2-4191-ac78-a015be66eb68_v2_1.stl" scale="0.001 0.001 0.001"/>
    </geometry>
    <material name="silver_default"/>
  </visual>
  <collision>
    <origin rpy="0 0 0" xyz="0.0 0.0 -0.050303"/>
    <geometry>
      <mesh filename="package://falcon_description/meshes/power_bank.f96af03a-0fb2-4191-ac78-a015be66eb68_v2_1.stl" scale="0.001 0.001 0.001"/>
    </geometry>
  </collision>
</link>

<link name="MODULO_XL4016_v1_1">
  <inertial>
    <origin rpy="0 0 0" xyz="0.0034963427787585875 0.1000045775850042 0.009725545612401736"/>
    <mass value="0.162841989737334"/>
    <inertia ixx="2.9e-05" ixy="0.0" ixz="-2e-06" iyy="4.9e-05" iyz="0.0" izz="6.5e-05"/>
  </inertial>
  <visual>
    <origin rpy="0 0 0" xyz="0.0 0.0 -0.054303"/>
    <geometry>
      <mesh filename="package://falcon_description/meshes/MODULO_XL4016_v1_1.stl" scale="0.001 0.001 0.001"/>
    </geometry>
    <material name="silver_default"/>
  </visual>
  <collision>
    <origin rpy="0 0 0" xyz="0.0 0.0 -0.054303"/>
    <geometry>
      <mesh filename="package://falcon_description/meshes/MODULO_XL4016_v1_1.stl" scale="0.001 0.001 0.001"/>
    </geometry>
  </collision>
</link>

<link name="Kinect_v8_1">
  <inertial>
    <origin rpy="0 0 0" xyz="0.05473293592494013 -0.00260847013176543 0.04806530798986494"/>
    <mass value="9.558158507460131"/>
    <inertia ixx="0.047723" ixy="-1.5e-05" ixz="1.9e-05" iyy="0.005195" iyz="-3e-06" izz="0.048191"/>
  </inertial>
  <visual>
    <origin rpy="0 0 0" xyz="0.001844 0.000887 -0.138303"/>
    <geometry>
      <mesh filename="package://falcon_description/meshes/Kinect_v8_1.stl" scale="0.001 0.001 0.001"/>
    </geometry>
    <material name="silver_default"/>
  </visual>
  <collision>
    <origin rpy="0 0 0" xyz="0.001844 0.000887 -0.138303"/>
    <geometry>
      <mesh filename="package://falcon_description/meshes/Kinect_v8_1.stl" scale="0.001 0.001 0.001"/>
    </geometry>
  </collision>
</link>

<link name="GY-91_MPU9250+BMP280_-_Pins_Down__1__v1_1">
  <inertial>
    <origin rpy="0 0 0" xyz="-0.0008173970150821562 -0.10039875418246093 0.0010166475259208788"/>
    <mass value="0.004104865550111833"/>
    <inertia ixx="0.0" ixy="-0.0" ixz="0.0" iyy="0.0" iyz="0.0" izz="0.0"/>
  </inertial>
  <visual>
    <origin rpy="0 0 0" xyz="0.0 0.0 -0.054303"/>
    <geometry>
      <mesh filename="package://falcon_description/meshes/GY-91_MPU9250+BMP280_-_Pins_Down__1__v1_1.stl" scale="0.001 0.001 0.001"/>
    </geometry>
    <material name="silver_default"/>
  </visual>
  <collision>
    <origin rpy="0 0 0" xyz="0.0 0.0 -0.054303"/>
    <geometry>
      <mesh filename="package://falcon_description/meshes/GY-91_MPU9250+BMP280_-_Pins_Down__1__v1_1.stl" scale="0.001 0.001 0.001"/>
    </geometry>
  </collision>
</link>

<link name="caster_2">
  <inertial>
    <origin rpy="0 0 0" xyz="0.11999999999999922 1.0995792177391875e-17 -0.022638739210345867"/>
    <mass value="0.24969771109813355"/>
    <inertia ixx="5.7e-05" ixy="-0.0" ixz="-0.0" iyy="5.7e-05" iyz="-0.0" izz="2.7e-05"/>
  </inertial>
  <visual>
    <origin rpy="0 0 0" xyz="0.0 0.0 -0.050303"/>
    <geometry>
      <mesh filename="package://falcon_description/meshes/caster_2.stl" scale="0.001 0.001 0.001"/>
    </geometry>
    <material name="silver_default"/>
  </visual>
  <collision>
    <origin rpy="0 0 0" xyz="0.0 0.0 -0.050303"/>
    <geometry>
      <mesh filename="package://falcon_description/meshes/caster_2.stl" scale="0.001 0.001 0.001"/>
    </geometry>
  </collision>
</link>

<joint name="Rigid1" type="fixed">
  <origin rpy="0 0 0" xyz="0.0 0.0 0.054303"/>
  <parent link="base_link"/>
  <child link="sd2_1"/>
</joint>

<joint name="Rigid2" type="fixed">
  <origin rpy="0 0 0" xyz="0.0 0.0 0.054303"/>
  <parent link="base_link"/>
  <child link="sd4_1"/>
</joint>

<joint name="Rigid3" type="fixed">
  <origin rpy="0 0 0" xyz="0.0 0.0 0.054303"/>
  <parent link="base_link"/>
  <child link="sd3_1"/>
</joint>

<joint name="Rigid4" type="fixed">
  <origin rpy="0 0 0" xyz="0.0 0.0 0.054303"/>
  <parent link="base_link"/>
  <child link="sd1_1"/>
</joint>

<joint name="Rigid5" type="fixed">
  <origin rpy="0 0 0" xyz="-0.10017 0.076294 0.08"/>
  <parent link="sd3_1"/>
  <child link="upper_plate_1"/>
</joint>

<joint name="Rigid6" type="fixed">
  <origin rpy="0 0 0" xyz="0.0 0.0 0.054303"/>
  <parent link="base_link"/>
  <child link="Arduino_uno.6df525b0-a0fc-4683-8e1a-4d70c617ad71_v1_1"/>
</joint>

<joint name="Rev9" type="continuous">
  <origin rpy="0 0 0" xyz="-0.0835 -0.1525 -0.012181"/>
  <parent link="motor_left_v1_1"/>
  <child link="wheels_v2_1"/>
  <axis xyz="0.0 -1.0 0.0"/>
</joint>

<joint name="Rev10" type="continuous">
  <origin rpy="0 0 0" xyz="-0.0837 0.1525 -0.016181"/>
  <parent link="motor_right_v1_v1_1"/>
  <child link="wheels_v2_2"/>
  <axis xyz="-0.0 1.0 -0.0"/>
</joint>

<joint name="Rigid12" type="fixed">
  <origin rpy="0 0 0" xyz="0.0 0.0 0.050303"/>
  <parent link="base_link"/>
  <child link="motor_left_v1_1"/>
</joint>

<joint name="Rigid13" type="fixed">
  <origin rpy="0 0 0" xyz="0.0 0.0 0.054303"/>
  <parent link="base_link"/>
  <child link="motor_right_v1_v1_1"/>
</joint>

<joint name="Rigid14" type="fixed">
  <origin rpy="0 0 0" xyz="0.0 0.0 0.054303"/>
  <parent link="base_link"/>
  <child link="Raspberry-Pi-4-Model-B-03_v1_1"/>
</joint>

<joint name="Rigid15" type="fixed">
  <origin rpy="0 0 0" xyz="0.0 0.0 0.054303"/>
  <parent link="base_link"/>
  <child link="l298n__v12_1"/>
</joint>

<joint name="Rigid16" type="fixed">
  <origin rpy="0 0 0" xyz="0.0 0.0 0.050303"/>
  <parent link="base_link"/>
  <child link="power_bank.f96af03a-0fb2-4191-ac78-a015be66eb68_v2_1"/>
</joint>

<joint name="Rigid17" type="fixed">
  <origin rpy="0 0 0" xyz="0.0 0.0 0.054303"/>
  <parent link="base_link"/>
  <child link="MODULO_XL4016_v1_1"/>
</joint>

<joint name="Rigid18" type="fixed">
  <origin rpy="0 0 0" xyz="0.098326 -0.077181 0.004"/>
  <parent link="upper_plate_1"/>
  <child link="Kinect_v8_1"/>
</joint>

<joint name="Rigid19" type="fixed">
  <origin rpy="0 0 0" xyz="0.0 0.0 0.054303"/>
  <parent link="base_link"/>
  <child link="GY-91_MPU9250+BMP280_-_Pins_Down__1__v1_1"/>
</joint>

<joint name="Rigid21" type="fixed">
  <origin rpy="0 0 0" xyz="0.0 0.0 0.050303"/>
  <parent link="base_link"/>
  <child link="caster_2"/>
</joint>

</robot>
